Workbook
Name tax_rate: DCF!$B$60
Name UPDATE: 'Data Sheet'!$E$1

Sheet DCF
A1: INCOME STATEMENT (CRORES)
A2: PARTICULARS | B2: FY 2021 | C2: FY 2022 | D2: FY 2023 | E2: FY 2024 | F2: FY 2025 | G2: CAGR
A3: Revenue from operations | B3: ='Data Sheet'!G17 -> 100472 | C3: ='Data Sheet'!H17 -> 121641 | D3: ='Data Sheet'!I17 -> 146767 | E3: ='Data Sheet'!J17 -> 153670 | F3: ='Data Sheet'!K17 -> 162990 | G3: =(F3/B3)^(1/4)-1 -> 0.12857124
A4: Employee cost | B4: ='Data Sheet'!G22 -> 55547 | C4: ='Data Sheet'!H22 -> 63997 | D4: ='Data Sheet'!I22 -> 78374 | E4: ='Data Sheet'!J22 -> 82636 | F4: ='Data Sheet'!K22 -> 85968
A5: Power & fuel | B5: ='Data Sheet'!G20 -> 143 | C5: ='Data Sheet'!H20 -> 132 | D5: ='Data Sheet'!I20 -> 176 | E5: ='Data Sheet'!J20 -> 199 | F5: ='Data Sheet'!K20 -> 222
A6: Subcontracting | B6: ='Data Sheet'!G21 -> 12800 | C6: ='Data Sheet'!H21 -> 20690 | D6: ='Data Sheet'!I21 -> 26330 | E6: ='Data Sheet'!J21 -> 27195 | F6: ='Data Sheet'!K21 -> 30395
A7: Selling&admin | B7: ='Data Sheet'!G23 -> 3194 | C7: ='Data Sheet'!H23 -> 4305 | D7: ='Data Sheet'!I23 -> 5300 | E7: ='Data Sheet'!J23 -> 5705 | F7: ='Data Sheet'!K23 -> 6039
A8: Other expenses | B8: ='Data Sheet'!G24 -> 899 | C8: ='Data Sheet'!H24 -> 1026 | D8: ='Data Sheet'!I24 -> 1457 | E8: ='Data Sheet'!J24 -> 1510 | F8: ='Data Sheet'!K24 -> 1130
A9: Total operating expense | B9: =SUM(B4:B8) -> 72583 | C9: =SUM(C4:C8) -> 90150 | D9: =SUM(D4:D8) -> 111637 | E9: =SUM(E4:E8) -> 117245 | F9: =SUM(F4:F8) -> 123754
A10: EBITDA | B10: =B3-B9 -> 27889 | C10: =C3-C9 -> 31491 | D10: =D3-D9 -> 35130 | E10: =E3-E9 -> 36425 | F10: =F3-F9 -> 39236 | G10: =(F10/B10)^(1/4)-1 -> 0.089087932
A11: EBITDA margin% | B11: =B10/B3 -> 0.27757982 | C11: =C10/C3 -> 0.25888475 | D11: =D10/D3 -> 0.23935898 | E11: =E10/E3 -> 0.2370339 | F11: =F10/F3 -> 0.24072642
A13: Depreciation | B13: ='Data Sheet'!G26 -> 3267 | C13: ='Data Sheet'!H26 -> 3476 | D13: ='Data Sheet'!I26 -> 4225 | E13: ='Data Sheet'!J26 -> 4678 | F13: ='Data Sheet'!K26 -> 4812
A14: %of sales | B14: =B13/B3 -> 0.032516522 | C14: =C13/C3 -> 0.028575891 | D14: =D13/D3 -> 0.028787125 | E14: =E13/E3 -> 0.030441856 | F14: =F13/F3 -> 0.029523284
A15: EBIT(Operating profit) | B15: =B10-B13 -> 24622 | C15: =C10-C13 -> 28015 | D15: =D10-D13 -> 30905 | E15: =E10-E13 -> 31747 | F15: =F10-F13 -> 34424
A16: EBIT margin% | B16: =B15/B3 -> 0.2450633 | C16: =C15/C3 -> 0.23030886 | D16: =D15/D3 -> 0.21057186 | E16: =E15/E3 -> 0.20659205 | F16: =F15/F3 -> 0.21120314
A18: Interest | B18: ='Data Sheet'!G27 -> 195 | C18: ='Data Sheet'!H27 -> 200 | D18: ='Data Sheet'!I27 -> 284 | E18: ='Data Sheet'!J27 -> 470 | F18: ='Data Sheet'!K27 -> 416
A19: Other income(non operating) | B19: ='Data Sheet'!G25 -> 2201 | C19: ='Data Sheet'!H25 -> 2295 | D19: ='Data Sheet'!I25 -> 2701 | E19: ='Data Sheet'!J25 -> 4711 | F19: ='Data Sheet'!K25 -> 3600
A20: Profit before tax | B20: ='Data Sheet'!G28 -> 26628 | C20: ='Data Sheet'!H28 -> 30110 | D20: ='Data Sheet'!I28 -> 33322 | E20: ='Data Sheet'!J28 -> 35988 | F20: ='Data Sheet'!K28 -> 37608
A21: Tax expense | B21: ='Data Sheet'!G29 -> 7205 | C21: ='Data Sheet'!H29 -> 7964 | D21: ='Data Sheet'!I29 -> 9214 | E21: ='Data Sheet'!J29 -> 9740 | F21: ='Data Sheet'!K29 -> 10858 | G21: =(F22/B22)^(1/4)-1 -> 0.083938926
A22: Net profit after tax | B22: ='Data Sheet'!G30 -> 19351 | C22: ='Data Sheet'!H30 -> 22110 | D22: ='Data Sheet'!I30 -> 24095 | E22: ='Data Sheet'!J30 -> 26233 | F22: ='Data Sheet'!K30 -> 26713
A25: BALANCE SHEET
A27: LIABILITIES
A28: Equit share capital | B28: ='Data Sheet'!G57 -> 2124 | C28: ='Data Sheet'!H57 -> 2098 | D28: ='Data Sheet'!I57 -> 2069 | E28: ='Data Sheet'!J57 -> 2071 | F28: ='Data Sheet'!K57 -> 2073
A29: reserves | B29: ='Data Sheet'!G58 -> 74227 | C29: ='Data Sheet'!H58 -> 73252 | D29: ='Data Sheet'!I58 -> 73338 | E29: ='Data Sheet'!J58 -> 86045 | F29: ='Data Sheet'!K58 -> 93745
A30: Total shareholders equity | B30: =B28+B29 -> 76351 | C30: =C28+C29 -> 75350 | D30: =D28+D29 -> 75407 | E30: =E28+E29 -> 88116 | F30: =F28+F29 -> 95818
A31: Borrowings | B31: ='Data Sheet'!G59 -> 5325 | C31: ='Data Sheet'!H59 -> 5474 | D31: ='Data Sheet'!I59 -> 8299 | E31: ='Data Sheet'!J59 -> 8359 | F31: ='Data Sheet'!K59 -> 8227
A32: Other liabilities | B32: ='Data Sheet'!G60 -> 25835 | C32: ='Data Sheet'!H60 -> 35905 | D32: ='Data Sheet'!I60 -> 40890 | E32: ='Data Sheet'!J60 -> 40885 | F32: ='Data Sheet'!K60 -> 43750
A33: Total liabilities | B33: =SUM(B30:B32) -> 107511 | C33: =SUM(C30:C32) -> 116729 | D33: =SUM(D30:D32) -> 124596 | E33: =SUM(E30:E32) -> 137360 | F33: =SUM(F30:F32) -> 147795
A34: ASSETS
A35: Fixed assets | B35: ='Data Sheet'!G62 -> 25505 | C35: ='Data Sheet'!H62 -> 25800 | D35: ='Data Sheet'!I62 -> 29225 | E35: ='Data Sheet'!J62 -> 27622 | F35: ='Data Sheet'!K62 -> 30961
A36: Capt work in progress | B36: ='Data Sheet'!G63 -> 922 | C36: ='Data Sheet'!H63 -> 416 | D36: ='Data Sheet'!I63 -> 288 | E36: ='Data Sheet'!J63 -> 293 | F36: ='Data Sheet'!K63 -> 814
A37: Investments | B37: ='Data Sheet'!G64 -> 14205 | C37: ='Data Sheet'!H64 -> 20324 | D37: ='Data Sheet'!I64 -> 19478 | E37: ='Data Sheet'!J64 -> 24623 | F37: ='Data Sheet'!K64 -> 23541
A38: Other assets | B38: ='Data Sheet'!G65 -> 66879 | C38: ='Data Sheet'!H65 -> 70189 | D38: ='Data Sheet'!I65 -> 75605 | E38: ='Data Sheet'!J65 -> 84822 | F38: ='Data Sheet'!K65 -> 92479
A39: Total assets | B39: =SUM(B35:B38) -> 107511 | C39: =SUM(C35:C38) -> 116729 | D39: =SUM(D35:D38) -> 124596 | E39: =SUM(E35:E38) -> 137360 | F39: =SUM(F35:F38) -> 147795
A41: KEY BALANCE SHEET ITEMS
A42: Receivables | B42: ='Data Sheet'!G67 -> 19294 | C42: ='Data Sheet'!H67 -> 22698 | D42: ='Data Sheet'!I67 -> 25424 | E42: ='Data Sheet'!J67 -> 30193 | F42: ='Data Sheet'!K67 -> 31158
A43: Cash&bank | B43: ='Data Sheet'!G69 -> 24714 | C43: ='Data Sheet'!H69 -> 17472 | D43: ='Data Sheet'!I69 -> 12173 | E43: ='Data Sheet'!J69 -> 14786 | F43: ='Data Sheet'!K69 -> 24455
A44: Net debt | B44: =B31-B43 -> -19389 | C44: =C31-C43 -> -11998 | D44: =D31-D43 -> -3874 | E44: =E31-E43 -> -6427 | F44: =F31-F43 -> -16228
A45: Check | B45: =B39-B33 -> 0 | C45: =C39-C33 -> 0 | D45: =D39-D33 -> 0 | E45: =E39-E33 -> 0 | F45: =F39-F33 -> 0
A48: KEY ASSUMPTIONS
...

Sheet CCM
A1: COMPANY COMPARABLE ANALYSIS
A3: COMPANY | B3: PRICE | C3: MARKET CAPT | D3: REVENUE | E3: EBITDA | F3: NET PROFIT | G3: BETA | H3: BORROWINGS | I3: CASH&BANK | J3: DEBT
A4: Infosys | B4: 1278.25 | C4: 518406.02 | D4: 162990 | E4: 39236 | F4: 26713 | G4: 0.9 | H4: 8227 | I4: 24455 | J4: 8796
A5: TCS | B5: 2384.2 | C5: 862624.52 | D5: 255324 | E5: 67407 | F5: 48797 | G5: 0.8 | H5: 9392 | I5: 15463 | J5: 10932
A6: HCL Technologies | B6: 1384.45 | C6: 375693.33 | D6: 117055 | E6: 25504 | F6: 4236 | G6: 1 | H6: 6276 | I6: 21289 | J6: 6780
A7: Wipro | B7: 188.9 | C7: 198126.12 | D7: 90892 | E7: 18021 | F7: 13218 | G7: 0.8 | H7: 19204 | I7: 12197 | J7: 16164
A8: Tech mahindra | B8: 1409 | C8: 138050 | D8: 52988 | E8: 6964 | F8: 4253 | G8: 0.9 | H8: 2025 | I8: 4542 | J8: 1954
A9: INDUSTRY BETA
A11: Company name | B11: Equity value | C11: Total debt | D11: Debt/equity | E11: Debt/capital | F11: Tax rate% | G11: Levered beta | H11: Unlevered beta
A12: TCS | B12: =C5 -> 862624.52 | C12: =J5 -> 10932 | D12: =C12/B12 -> 0.012672953 | E12: =C12/(B12+C12) -> 0.012514359 | F12: =tax_rate -> 0.28 | G12: =G5 -> 0.8 | H12: =G12/(1+D12*(1-F12)) -> 0.79276638
A13: HCL Technologies | B13: =C6 -> 375693.33 | C13: =J6 -> 6780 | D13: =C13/B13 -> 0.018046634 | E13: =C13/(B13+C13) -> 0.017726726 | F13: =tax_rate -> 0.28 | G13: =G6 -> 1 | H13: =G13/(1+D13*(1-F13)) -> 0.98717309
A14: Wipro | B14: =C7 -> 198126.12 | C14: =J7 -> 16164 | D14: =C14/B14 -> 0.081584397 | E14: =C14/(B14+C14) -> 0.075430449 | F14: =tax_rate -> 0.28 | G14: =G7 -> 0.8 | H14: =G14/(1+D14*(1-F14)) -> 0.75561462
A15: Tech mahindra | B15: =C8 -> 138050 | C15: =J8 -> 1954 | D15: =C15/B15 -> 0.014154292 | E15: =C15/(B15+C15) -> 0.013956744 | F15: =tax_rate -> 0.28 | G15: =G8 -> 0.9 | H15: =G15/(1+D15*(1-F15)) -> 0.89092055
A16: AVERAGE | D16: =AVERAGE(D12:D15) -> 0.031614569 | E16: =AVERAGE(E12:E15) -> 0.02990707 | F16: =AVERAGE(F12:F15) -> 0.28 | G16: =AVERAGE(G12:G15) -> 0.875 | H16: =AVERAGE(H12:H15) -> 0.85661866
A17: MEDIAN | D17: =MEDIAN(D12:D15) -> 0.016100463 | E17: =MEDIAN(E12:E15) -> 0.015841735 | F17: =MEDIAN(F12:F15) -> 0.28 | G17: =MEDIAN(G12:G15) -> 0.85 | H17: =MEDIAN(H12:H15) -> 0.84184347

Sheet Data Sheet
A1: COMPANY NAME | B1: INFOSYS LTD | E1: =IF(B2<>B3, "A NEW VERSION OF THE WORKSHEET IS AVAILABLE", "")
A2: LATEST VERSION | B2: 2.1 | E2: PLEASE DO NOT MAKE ANY CHANGES TO THIS SHEET
A3: CURRENT VERSION | B3: 2.1
A5: META
A6: Number of shares | B6: =IF(B9>0, B9/B8, 0) -> 405.55919
A7: Face Value | B7: 5
A8: Current Price | B8: 1268.9
A9: Market Capitalization | B9: 514614.05
A15: PROFIT & LOSS
A16: Report Date | B16: 42460 | C16: 42825 | D16: 43190 | E16: 43555 | F16: 43921 | G16: 44286 | H16: 44651 | I16: 45016 | J16: 45382 | K16: 45747
A17: Sales | B17: 62441 | C17: 68484 | D17: 70522 | E17: 82675 | F17: 90791 | G17: 100472 | H17: 121641 | I17: 146767 | J17: 153670 | K17: 162990
A18: Raw Material Cost
A19: Change in Inventory
A20: Power and Fuel | B20: 217 | C20: 228 | D20: 207 | E20: 221 | F20: 229 | G20: 143 | H20: 132 | I20: 176 | J20: 199 | K20: 222
A21: Other Mfr. Exp | B21: 5860 | C21: 6712 | D21: 7286 | E21: 9902 | F21: 11086 | G21: 12800 | H21: 20690 | I21: 26330 | J21: 27195 | K21: 30395
A22: Employee Cost | B22: 34415 | C22: 37669 | D22: 38902 | E22: 45323 | F22: 50895 | G22: 55547 | H22: 63997 | I22: 78374 | J22: 82636 | K22: 85968
A23: Selling and admin | B23: 4441 | C23: 4584 | D23: 4585 | E23: 5553 | F23: 5375 | G23: 3194 | H23: 4305 | I23: 5300 | J23: 5705 | K23: 6039
A24: Other Expenses | B24: 429 | C24: 687 | D24: 720 | E24: 1506 | F24: 939 | G24: 899 | H24: 1026 | I24: 1457 | J24: 1510 | K24: 1130
A25: Other Income | B25: 3120 | C25: 3050 | D25: 3311 | E25: 2882 | F25: 2803 | G25: 2201 | H25: 2295 | I25: 2701 | J25: 4711 | K25: 3600
A26: Depreciation | B26: 1459 | C26: 1703 | D26: 1863 | E26: 2011 | F26: 2893 | G26: 3267 | H26: 3476 | I26: 4225 | J26: 4678 | K26: 4812
A27: Interest | F27: 170 | G27: 195 | H27: 200 | I27: 284 | J27: 470 | K27: 416
A28: Profit before tax | B28: 18740 | C28: 19951 | D28: 20270 | E28: 21041 | F28: 22007 | G28: 26628 | H28: 30110 | I28: 33322 | J28: 35988 | K28: 37608
A29: Tax | B29: 5251 | C29: 5598 | D29: 4241 | E29: 5631 | F29: 5368 | G29: 7205 | H29: 7964 | I29: 9214 | J29: 9740 | K29: 10858
A30: Net profit | B30: 13489 | C30: 14353 | D30: 16029 | E30: 15404 | F30: 16594 | G30: 19351 | H30: 22110 | I30: 24095 | J30: 26233 | K30: 26713
A31: Dividend Amount | B31: 5548.4 | C31: 5891.6 | D31: 9465.6 | E31: 9222.5 | F31: 7427 | G31: 11469.6 | H31: 13007.6 | I31: 14069.2 | J31: 19053.2 | K31: 17827.8
A40: Quarters
A41: Report Date | B41: 45199 | C41: 45291 | D41: 45382 | E41: 45473 | F41: 45565 | G41: 45657 | H41: 45747 | I41: 45838 | J41: 45930 | K41: 46022
A42: Sales | B42: 38994 | C42: 38821 | D42: 37923 | E42: 39315 | F42: 40986 | G42: 41764 | H42: 40925 | I42: 42279 | J42: 44490 | K42: 45479
A43: Expenses | B43: 29554 | C43: 29684 | D43: 29139 | E43: 29878 | F43: 31177 | G43: 31649 | H43: 31051 | I43: 32336 | J43: 33955 | K43: 34845
A44: Other Income | B44: 632 | C44: 789 | D44: 2729 | E44: 838 | F44: 712 | G44: 859 | H44: 1190 | I44: 1042 | J44: 982 | K44: -150
A45: Depreciation | B45: 1166 | C45: 1176 | D45: 1163 | E45: 1149 | F45: 1160 | G45: 1203 | H45: 1299 | I45: 1140 | J45: 1182 | K45: 1155
A46: Interest | B46: 138 | C46: 131 | D46: 110 | E46: 105 | F46: 108 | G46: 101 | H46: 102 | I46: 105 | J46: 106 | K46: 100
A47: Profit before tax | B47: 8768 | C47: 8619 | D47: 10240 | E47: 9021 | F47: 9253 | G47: 9670 | H47: 9663 | I47: 9740 | J47: 10229 | K47: 9229
A48: Tax | B48: 2553 | C48: 2506 | D48: 2265 | E48: 2647 | F48: 2737 | G48: 2848 | H48: 2625 | I48: 2816 | J48: 2854 | K48: 2563
A49: Net profit | B49: 6212 | C49: 6106 | D49: 7969 | E49: 6368 | F49: 6506 | G49: 6806 | H49: 7033 | I49: 6921 | J49: 7364 | K49: 6654
A50: Operating Profit | B50: 9440 | C50: 9137 | D50: 8784 | E50: 9437 | F50: 9809 | G50: 10115 | H50: 9874 | I50: 9943 | J50: 10535 | K50: 10634
A55: BALANCE SHEET
A56: Report Date | B56: 42460 | C56: 42825 | D56: 43190 | E56: 43555 | F56: 43921 | G56: 44286 | H56: 44651 | I56: 45016 | J56: 45382 | K56: 45747
A57: Equity Share Capital | B57: 1144 | C57: 1144 | D57: 1088 | E57: 2170 | F57: 2122 | G57: 2124 | H57: 2098 | I57: 2069 | J57: 2071 | K57: 2073
A58: Reserves | B58: 60600 | C58: 67838 | D58: 63835 | E58: 62778 | F58: 63328 | G58: 74227 | H58: 73252 | I58: 73338 | J58: 86045 | K58: 93745
...
